<?xml version="1.0"?>
<robot xmlns:xacro="http://www.ros.org/wiki/xacro" name="r_wheel">
    <xacro:include filename="$(find robot_description)/urdf/properties.xacro"/>
    <xacro:macro name="wheel" params="name translation rotation parent">
        <link name="${name}_wheel">
            <visual>
                <origin xyz="0 0 0" rpy="0 0 0"/>
                <geometry>
                    <mesh filename="package://robot_description/Mash/WL_Link.STL" scale="1 1 1"/>
                </geometry>
            </visual>

            <collision>
                <origin xyz="0.0 0.0 0" rpy="0.0 ${PI/2} 0" />
                <geometry>
                    <cylinder radius="${RB_WHEEL_R/2}" length="${length_WHEEL}" />
                </geometry>
            </collision>
            <inertial>
                <origin xyz="0.0 0.0 0.0" rpy="0.0 0.0 0.0" />
                <mass value="0.02668" />
                <inertia 	
                    ixx = "0.00002"	ixy = "0.00000"	ixz = "0.00000"
	                iyx = "0.00000"	iyy = "0.00001"	iyz = "0.00000"
	                izx = "0.00000"	izy = "0.00000"	izz = "0.00001" />
            </inertial>
        </link>
        <joint name="${name}_wheel_joint" type="continuous">
            <origin xyz="${translation}" rpy="${rotation}"/>
            <parent link="${parent}"/>
            <child link="${name}_wheel"/>
            <axis xyz="1 0 0"/>
            <limit effort="${U_MAX}" velocity="${V_MAX}"/>
            <dynamics damping="${WHEEL_JOINT_DAMP}"/>
            
        </joint>
        <gazebo reference="${name}_wheel">
            <material>Gazebo/Yellow</material>
        </gazebo>
    </xacro:macro>
</robot>